<?xml version="1.0" encoding="utf-8"?>
<robot name="arm" xmlns:xacro="http://ros.org/wiki/xacro">
  <xacro:property name="M_PI"   value="3.1415926535897931"/>

  <link  
    name="arm_base_link"> <!-- 机械臂底座 -->
    <inertial>
      <origin
        xyz="9.55287669839149E-05 0.000953445773182543 0.0181622223429797"
        rpy="0 0 0" />
      <mass
        value="0.018996290781889" />
      <inertia
        ixx="3.52401713486466E-06"
        ixy="-9.57766622211234E-11"
        ixz="1.77834467690429E-11"
        iyy="2.92480468671507E-06"
        iyz="2.27263787135776E-08"
        izz="2.43231516201483E-06" />
    </inertial>
    <visual>
      <origin
        xyz="0 0 0"
        rpy="0 0 0" />
      <geometry>
        <mesh
          filename="package://kai01_description/meshes/arm/arm_base_link.STL" />
      </geometry>
      <material name="green"/>
    </visual>
    <collision>
      <origin
        xyz="0 0 0"
        rpy="0 0 0" />
      <geometry>
        <mesh
          filename="package://kai01_description/meshes/arm/arm_base_link.STL" />
      </geometry>
    </collision>
  </link>

  <joint
    name="arm_base_link_to_servo_2"
    type="fixed">
    <origin
      xyz="0 0 0"
      rpy="0 0 0" />
    <parent
      link="arm_base_link" />
    <child
      link="servo_2" />
    <axis
      xyz="0 0 0" />
  </joint>

  <link
    name="servo_2"><!-- 2号舵机 -->
    <inertial>
      <origin
        xyz="6.74971199241745E-05 -0.00653404855626152 0.0238958340366914"
        rpy="0 0 0" />
      <mass
        value="0.0116330609777772" />
      <inertia
        ixx="1.75977694435981E-06"
        ixy="-9.73060826949638E-11"
        ixz="2.47639220332551E-12"
        iyy="2.04910641988494E-06"
        iyz="-1.98639869902586E-08"
        izz="5.57260556249774E-07" />
    </inertial>
    <visual>
      <origin
        xyz="0 0 0"
        rpy="0 0 0" />
      <geometry>
        <mesh
          filename="package://kai01_description/meshes/arm/servo_link1.STL" />
      </geometry>
      <material name="black"/>
    </visual>
    <collision>
      <origin
        xyz="0 0 0"
        rpy="0 0 0" />
      <geometry>
        <mesh
          filename="package://kai01_description/meshes/arm/servo_link1_collision.stl" />
      </geometry>
    </collision>
  </link>

  <joint
    name="arm_joint2"
    type="revolute">
    <origin
      xyz="0 0 0.0338648012164686"
      rpy="0 0 0" />
    <parent
      link="servo_2" />
    <child
      link="Link_1" />
    <axis
      xyz="0 1 0" />
    <limit
      lower="-2.09"
      upper="2.09"
      effort="1000"
      velocity="10" />
  </joint>

  <link
    name="Link_1"><!-- 连杆-1 -->
    <inertial>
      <origin
        xyz="0.000156299570425157 -0.000455113699913916 0.0717727028511975"
        rpy="0 0 0" />
      <mass
        value="0.0329250074531705" />
      <inertia
        ixx="3.91620966174037E-05"
        ixy="-5.45461883923424E-11"
        ixz="-1.84994427464167E-07"
        iyy="3.08453562297899E-05"
        iyz="3.5881427402197E-09"
        izz="1.15081900975983E-05" />
    </inertial>
    <visual>
      <origin
        xyz="0 0 0"
        rpy="0 0 0" />
      <geometry>
        <mesh
          filename="package://kai01_description/meshes/arm/Link_1.STL" />
      </geometry>
      <material name="green"/>
    </visual>
    <collision>
      <origin
        xyz="0 0 0"
        rpy="0 0 0" />
      <geometry>
        <mesh
          filename="package://kai01_description/meshes/arm/Link_1_collision.stl" />
      </geometry>
    </collision>
  </link>


  <joint
    name="arm_joint3"
    type="revolute">
    <origin
      xyz="0 0 0.129444631186569"
      rpy="0 0 0" />
    <parent
      link="Link_1" />
    <child
      link="Link_2" />
    <axis
      xyz="0 1 0" />
    <limit
      lower="-2.09"
      upper="2.09"
      effort="1000"
      velocity="10" />
  </joint>

  <link
    name="Link_2"><!-- 连接杆-2 -->
    <inertial>
      <origin
        xyz="0.000128456440925698 -0.000761424622733717 0.071772743785429"
        rpy="0 0 0" />
      <mass
        value="0.0329250074463074" />
      <inertia
        ixx="3.91621699579612E-05"
        ixy="-5.40097530558062E-11"
        ixz="-1.73786652512013E-07"
        iyy="3.08451969920239E-05"
        iyz="3.63874236522223E-09"
        izz="1.15078234912494E-05" />
    </inertial>
    <visual>
      <origin
        xyz="0 0 0"
        rpy="0 0 0" />
      <geometry>
        <mesh
          filename="package://kai01_description/meshes/arm/Link_2.STL" />
      </geometry>
      <material name="green"/>
    </visual>
    <collision>
      <origin
        xyz="0 0 0"
        rpy="0 0 0" />
      <geometry>
        <mesh
          filename="package://kai01_description/meshes/arm/Link_2_collision.stl" />
      </geometry>
    </collision>
  </link>

  <joint
    name="arm_joint4"
    type="revolute">
    <origin
      xyz="0 0 0.129444631186569"
      rpy="0 0 0" />
    <parent
      link="Link_2" />
    <child
      link="Link_3" />
    <axis
      xyz="0 1 0" />
    <limit
      lower="-2.09"
      upper="2.09"
      effort="1000"
      velocity="10" />
  </joint>

  <link
    name="Link_3"><!-- 连接杆-3 -->
    <inertial>
      <origin
        xyz="-0.000261855576526311 0.000239368359066633 0.0220971301535388"
        rpy="0 0 0" />
      <mass
        value="0.00959141779390409" />
      <inertia
        ixx="7.94977139591732E-06"
        ixy="-8.29446018776969E-10"
        ixz="5.6880898756802E-08"
        iyy="4.29063067361656E-06"
        iyz="-1.84622131688891E-10"
        izz="5.33833388813501E-06" />
    </inertial>
    <visual>
      <origin
        xyz="0 0 0"
        rpy="0 0 0" />
      <geometry>
        <mesh
          filename="package://kai01_description/meshes/arm/Link_3.STL" />
      </geometry>
      <material name="green"/>
    </visual>
    <collision>
      <origin
        xyz="0 0 0"
        rpy="0 0 0" />
      <geometry>
        <mesh
          filename="package://kai01_description/meshes/arm/Link_3_collision.stl" />
      </geometry>
    </collision>
  </link>

  <joint
    name="Link_3_to_servo_5"
    type="fixed">
    <origin
      xyz="0 0 0.0544833339503674"
      rpy="0 0 0" />
    <parent
      link="Link_3" />
    <child
      link="servo_5" />
    <axis
      xyz="0 0 0" />
  </joint>

  <link
    name="servo_5"><!-- 4号舵机 -->
    <inertial>
      <origin
        xyz="0.00829457691057159 0.000114732113040695 -0.0125525321145837"
        rpy="0 0 0" />
      <mass
        value="0.00701021225113507" />
      <inertia
        ixx="6.10646998888003E-07"
        ixy="1.66839713815154E-09"
        ixz="-2.07626862362467E-08"
        iyy="9.477990166652E-07"
        iyz="5.12927100881908E-09"
        izz="1.44691449724265E-06" />
    </inertial>
    <visual>
      <origin
        xyz="0 0 0"
        rpy="0 0 0" />
      <geometry>
        <mesh
          filename="package://kai01_description/meshes/arm/servo_5.STL" />
      </geometry>
      <material name="black"/>
    </visual>
    <collision>
      <origin
        xyz="0 0 0"
        rpy="0 0 0" />
      <geometry>
        <mesh
          filename="package://kai01_description/meshes/arm/servo_5_collision.stl" />
      </geometry>
    </collision>
  </link>

  <joint
    name="arm_joint5"
    type="revolute">
    <origin
      xyz="0 0 0"
      rpy="0 0 0" />
    <parent
      link="servo_5" />
    <child
      link="coupling" />
    <axis
      xyz="0 0 -1" />
    <limit
      lower="-2.09"
      upper="2.09"
      effort="1000"
      velocity="10" />
  </joint>

  <link
    name="coupling"> <!-- 舵机连轴圆盘 -->
    <inertial>
      <origin
        xyz="-5.40141895711381E-05 -8.30141354428709E-06 0.00351551092860852"
        rpy="0 0 0" />
      <mass
        value="0.00101775298619909" />
      <inertia
        ixx="2.35834256739382E-08"
        ixy="-1.92177809145012E-12"
        ixz="-3.88572739181837E-12"
        iyy="2.35740360938003E-08"
        iyz="-1.1228386368903E-13"
        izz="4.40224050991292E-08" />
    </inertial>
    <visual>
      <origin
        xyz="0 0 0"
        rpy="0 0 0" />
      <geometry>
        <mesh
          filename="package://kai01_description/meshes/arm/coupling.STL" />
      </geometry>
      <material name="black"/>
    </visual>
    <collision>
      <origin
        xyz="0 0 0"
        rpy="0 0 0" />
      <geometry>
        <mesh
          filename="package://kai01_description/meshes/arm/coupling.STL" />
      </geometry>
    </collision>
  </link>

  <joint
    name="gripper_joint"
    type="fixed">
    <origin
      xyz="0 0 0.0054388"
      rpy="0 0 0" />
    <parent
      link="coupling" />
    <child
      link="servo_6" />
    <axis
      xyz="0 0 0" />
  </joint>


  <link
    name="servo_6">
    <inertial>
      <origin
        xyz="0.0145481835889059 -0.00315257290321308 0.0253492053712461"
        rpy="0 0 0" />
      <mass
        value="0.0174988490314194" />
      <inertia
        ixx="4.12615692688456E-06"
        ixy="-2.75102939068049E-08"
        ixz="-7.61180742281118E-09"
        iyy="1.57023365316943E-06"
        iyz="2.2563082379695E-08"
        izz="3.2612101868791E-06" />
    </inertial>
    <visual>
      <origin
        xyz="0 0 0"
        rpy="0 0 0" />
      <geometry>
        <mesh
          filename="package://kai01_description/meshes/arm/servo_6.STL" />
      </geometry>
      <material name="black"/>
    </visual>
    <collision>
      <origin
        xyz="0 0 0"
        rpy="0 0 0" />
      <geometry>
        <mesh
          filename="package://kai01_description/meshes/arm/servo_6_collision.stl" />
      </geometry>
    </collision>
  </link>

<!-- 夹爪部分 -->
   <link
    name="r_link"><!-- 夹爪右齿轮 -->
    <inertial>
      <origin
        xyz="0.00154652142582958 0.000534112070478834 0.00624030428121536"
        rpy="0 0 0" />
      <mass
        value="0.00206265647704866" />
      <inertia
        ixx="3.97215843669342E-07"
        ixy="-2.75699120579387E-10"
        ixz="-2.19901048536124E-09"
        iyy="3.22472627342115E-07"
        iyz="1.07303783544668E-08"
        izz="7.78708186672131E-08" />
    </inertial>
    <visual>
      <origin
        xyz="0 0 0"
        rpy="0 0 0" />
      <geometry>
        <mesh
          filename="package://kai01_description/meshes/gripper/r_link.STL" />
      </geometry>
      <material name="black"/>
    </visual>
    <collision>
      <origin
        xyz="0 0 0"
        rpy="0 0 0" />
      <geometry>
        <mesh
          filename="package://kai01_description/meshes/gripper/r_link.STL" />
      </geometry>
    </collision>
  </link>

  <joint
    name="arm_joint6"
    type="revolute">
    <origin
      xyz="-0.0073166 -0.013992 0.027059" 
      rpy="0 0 0" />
    <parent
      link="servo_6" />
    <child
      link="r_link" />
    <axis
      xyz="0.99996 -0.004699 -0.0070434" />
    <limit
      lower="0"
      upper="1.57"
      effort="1000"
      velocity="10" />
  </joint>


  <link
    name="l_link">  <!-- 夹爪左齿轮 -->
    <inertial>
      <origin
        xyz="0.0015384031888858 -0.000403232726847674 0.00579759783012201"
        rpy="0 0 0" />
      <mass
        value="0.00218924933187322" />
      <inertia
        ixx="4.0534152698165E-07"
        ixy="3.60077827494503E-10"
        ixz="-1.99675888093364E-09"
        iyy="3.31222174181852E-07"
        iyz="-8.79337758250917E-09"
        izz="7.74319582642917E-08" />
    </inertial>
    <visual>
      <origin
        xyz="0 0 0"
        rpy="0 0 0" />
      <geometry>
        <mesh
          filename="package://kai01_description/meshes/gripper/l_link.STL" />
      </geometry>
      <material name="black"/>
    </visual>
    <collision>
      <origin
        xyz="0 0 0"
        rpy="0 0 0" />
      <geometry>
        <mesh
          filename="package://kai01_description/meshes/gripper/l_link.STL" />
      </geometry>
    </collision>
  </link>

  <joint
    name="l_joint"
    type="revolute">
    <origin
      xyz="-0.0073352 0.013977 0.027057"
      rpy="0 0 0" />
    <parent
      link="servo_6" />
    <child
      link="l_link" />
    <axis
      xyz="0.99997 0.0055811 -0.0058397" />
    <limit
      lower="-1.57"
      upper="1.57"
      effort="1000"
      velocity="10" />
    <mimic
      joint="arm_joint6"
      multiplier="-1"
      offset="0" />
  </joint>

  <link
    name="l_in_link">  <!-- 左侧夹爪连杆 -->
    <inertial>
      <origin
        xyz="0.00610191812065245 2.91459132896708E-05 0.0144573768632076"
        rpy="0 0 0" />
      <mass
        value="0.000776872870694597" />
      <inertia
        ixx="9.87455572181138E-08"
        ixy="5.06340928475727E-12"
        ixz="-6.79685646256186E-10"
        iyy="9.76635148452203E-08"
        iyz="-6.12115908323794E-12"
        izz="2.25695364751658E-09" />
    </inertial>
    <visual>
      <origin
        xyz="0 0 0"
        rpy="0 0 0" />
      <geometry>
        <mesh
          filename="package://kai01_description/meshes/gripper/l_in_link.STL" />
      </geometry>
      <material name="black"/>
    </visual>
    <collision>
      <origin
        xyz="0 0 0"
        rpy="0 0 0" />
      <geometry>
        <mesh
          filename="package://kai01_description/meshes/gripper/l_in_link.STL" />
      </geometry>
    </collision>
  </link>
  <joint
    name="l_in_joint"
    type="revolute">
    <origin
      xyz="-0.0071623 0.0049403 0.046019"
      rpy="0 0 0" />
    <parent
      link="servo_6" />
    <child
      link="l_in_link" />
    <axis
      xyz="0.99996 0.0046983 -0.0070439" />
    <limit
      lower="-1.57"
      upper="1.57"
      effort="1000"
      velocity="10" />
    <mimic
      joint="arm_joint6"
      multiplier="-1"
      offset="0" />
  </joint>

  <link
    name="l_out_link">   <!-- 左侧外夹爪 -->
    <inertial>
      <origin
        xyz="0.00602407836518577 0.0014461936314294 0.00961214041434189"
        rpy="0 0 0" />
      <mass
        value="0.00384735908281124" />
      <inertia
        ixx="8.77337978935691E-07"
        ixy="1.36760329013846E-09"
        ixz="-6.9462127438421E-09"
        iyy="8.19648792008027E-07"
        iyz="1.56177294727923E-07"
        izz="7.0687486597803E-08" />
    </inertial>
    <visual>
      <origin
        xyz="0 0 0"
        rpy="0 0 0" />
      <geometry>
        <mesh
          filename="package://kai01_description/meshes/gripper/l_out_link.STL" />
      </geometry>
      <material name="black"/>
    </visual>
    <collision>
      <origin
        xyz="0 0 0"
        rpy="0 0 0" />
      <geometry>
        <mesh
          filename="package://kai01_description/meshes/gripper/l_out_link.STL" />
      </geometry>
    </collision>
  </link>

  <joint
    name="l_out_joint"
    type="revolute">
    <origin
      xyz="0.00020427 0 0.028999"
      rpy="0 0 0" />
    <parent
      link="l_in_link" />
    <child
      link="l_out_link" />
    <axis
      xyz="0.99996 0.0046983 -0.0070439" />
    <limit
      lower="-1.57"
      upper="1.57"
      effort="1000"
      velocity="10" />
    <mimic
      joint="arm_joint6"
      multiplier="1"
      offset="0" />
  </joint>

  <link
    name="r_in_link">   <!-- 右侧夹爪连杆 -->
    <inertial>
      <origin
        xyz="0.00610191812065006 -2.81924690068705E-05 0.0144573787538957"
        rpy="0 0 0" />
      <mass
        value="0.000776872870694522" />
      <inertia
        ixx="9.87465668171204E-08"
        ixy="-5.11173808106636E-12"
        ixz="-6.79692406191707E-10"
        iyy="9.7664293636849E-08"
        iyz="-5.14018800149497E-13"
        izz="2.25718458778487E-09" />
    </inertial>
    <visual>
      <origin
        xyz="0 0 0"
        rpy="0 0 0" />
      <geometry>
        <mesh
          filename="package://kai01_description/meshes/gripper/r_in_link.STL" />
      </geometry>
      <material name="black"/>
    </visual>
    <collision>
      <origin
        xyz="0 0 0"
        rpy="0 0 0" />
      <geometry>
        <mesh
          filename="package://kai01_description/meshes/gripper/r_in_link.STL" />
      </geometry>
    </collision>
  </link>

  <joint
    name="r_in_joint"
    type="revolute">
    <origin
      xyz="-0.0071623 -0.004943 0.046019"
      rpy="0 0 0" />
    <parent
      link="servo_6" />
    <child
      link="r_in_link" />
    <axis
      xyz="-0.99996 0.0046987 0.0070436" />
    <limit
      lower="-1.57"
      upper="1.57"
      effort="1000"
      velocity="10" />
    <mimic
      joint="arm_joint6"
      multiplier="-1"
      offset="0" />
  </joint>

  <link
    name="r_out_link">   <!-- 右侧外夹爪 -->
    <inertial>
      <origin
        xyz="0.0060622 -0.0014474 0.0096107"
        rpy="0 0 0" />
      <mass
        value="0.0038474" />
      <inertia
        ixx="8.7734E-07"
        ixy="-1.2815E-09"
        ixz="-6.7006E-09"
        iyy="8.1957E-07"
        iyz="-1.5635E-07"
        izz="7.0761E-08" />
    </inertial>
    <visual>
      <origin
        xyz="0 0 0"
        rpy="0 0 0" />
      <geometry>
        <mesh
          filename="package://kai01_description/meshes/gripper/r_out_link.STL" />
      </geometry>
      <material name="black"/>
    </visual>
    <collision>
      <origin
        xyz="0 0 0"
        rpy="0 0 0" />
      <geometry>
        <mesh
          filename="package://kai01_description/meshes/gripper/r_out_link.STL" />
      </geometry>
    </collision>
  </link>

  <joint
    name="r_out_joint"
    type="revolute">
    <origin
      xyz="0.00020427 0 0.028999"
      rpy="0 0 0" />
    <parent
      link="r_in_link" />
    <child
      link="r_out_link" />
    <axis
      xyz="-0.99996 0.0046987 0.0070436" />
    <limit
      lower="-1.57"
      upper="1.57"
      effort="1000"
      velocity="10" />
    <mimic
      joint="arm_joint6"
      multiplier="1"
      offset="0" />
  </joint>


<!-- 深度相机部分 -->
  <link
    name="camera_connect_link">
    <inertial>
      <origin
        xyz="-0.00050566 0.010186 0.0012735"
        rpy="0 0 0" />
      <mass
        value="0.0029007" />
      <inertia
        ixx="4.5276E-07"
        ixy="-3.2151E-10"
        ixz="-8.627E-12"
        iyy="5.4068E-07"
        iyz="-1.2081E-08"
        izz="9.9085E-07" />
    </inertial>
    <visual>
      <origin
        xyz="0 0 0"
        rpy="0 0 0" />
      <geometry>
        <mesh
          filename="package://kai01_description/meshes/arm/camera_connect_link.STL" />
      </geometry>
      <material name="black"/>
    </visual>
    <collision>
      <origin
        xyz="0 0 0"
        rpy="0 0 0" />
      <geometry>
        <mesh
          filename="package://kai01_description/meshes/arm/camera_connect_link.STL" />
      </geometry>
    </collision>
  </link>

  <joint
    name="camera_connect_joint"
    type="fixed">
    <origin
      xyz="-0.0507060266977644 0 0.0505384841187764"
      rpy="0 0 -1.57079632679489" />
    <parent
      link="Link_3" />
    <child
      link="camera_connect_link" />
    <axis
      xyz="0 0 0" />
  </joint>


  <link
    name="camera_link"> <!-- 深度相机 -->
    <inertial>
      <origin
        xyz="0.00232981322860787 0.000387137406184821 -2.84059740606052E-05"
        rpy="0 0 0" />
      <mass
        value="0.015428" />
      <inertia
        ixx="1.3945E-06"
        ixy="-1.5684E-08"
        ixz="-2.3104E-07"
        iyy="1.2848E-05"
        iyz="1.3156E-09"
        izz="1.361E-05" />
    </inertial>
    <visual>
      <origin
        xyz="0 0 0"
        rpy="0 0 0" />
      <geometry>
        <mesh
          filename="package://kai01_description/meshes/arm/depth_cam_link.STL" />
      </geometry>
      <material
        name="">
        <color
          rgba="0.753 0.753 0.753 1" />
      </material>
    </visual>
    <collision>
      <origin
        xyz="0 0 0"
        rpy="0 0 0" />
      <geometry>
        <mesh
          filename="package://kai01_description/meshes/arm/depth_cam_link_collision.stl" />
      </geometry>
    </collision>
  </link>

  <joint
    name="depth_cam_joint"
    type="fixed">
    <origin
      xyz="0 0.0 0.014475"
      rpy="${M_PI} -${M_PI/2} -${M_PI/2}"/>
    <parent
      link="camera_connect_link" />
    <child
      link="camera_link" />
    <axis
      xyz="0 0 0" />
  </joint>


</robot>
